<?xml version="1.0" encoding="utf-8"?>
<!-- This URDF was automatically created by SolidWorks to URDF Exporter! Originally created by Stephen Brawner (brawner@gmail.com) 
     Commit Version: 1.5.1-0-g916b5db  Build Version: 1.5.7152.31018
     For more information, please see http://wiki.ros.org/sw_urdf_exporter -->
<robot name="qxrobot_urdf_v1">
  <link name="base_link">
    <inertial>
      <origin
        xyz="-0.0107573806983678 -0.000121111379146382 0.168820068401291"
        rpy="0 0 0" />
      <mass
        value="7.75262327008847" />
      <inertia
        ixx="0.0674364406464489"
        ixy="2.6530001859869E-06"
        ixz="-2.02885454828053E-06"
        iyy="0.0607129183001536"
        iyz="-2.82546028667119E-08"
        izz="0.117886359812438" />
    </inertial>
    <visual>
      <origin
        xyz="0 0 0"
        rpy="0 0 0" />
      <geometry>
        <mesh
          filename="package://qxrobot_urdf_v1/meshes/base_link.STL" />
      </geometry>
      <material
        name="">
        <color
          rgba="0.752941176470588 0.752941176470588 0.752941176470588 1" />
      </material>
    </visual>
    <collision>
      <origin
        xyz="0 0 0"
        rpy="0 0 0" />
      <geometry>
        <mesh
          filename="package://qxrobot_urdf_v1/meshes/base_link.STL" />
      </geometry>
    </collision>
  </link>
  <link
    name="turn_front_left_link">
    <inertial>
      <origin
        xyz="2.4774E-06 -4.2768E-06 -0.041346"
        rpy="0 0 0" />
      <mass
        value="0.1509" />
      <inertia
        ixx="8.621E-05"
        ixy="-2.6953E-09"
        ixz="-8.1387E-10"
        iyy="5.4519E-05"
        iyz="1.5042E-09"
        izz="6.6419E-05" />
    </inertial>
    <visual>
      <origin
        xyz="0 0 0"
        rpy="0 0 0" />
      <geometry>
        <mesh
          filename="package://qxrobot_urdf_v1/meshes/turn_front_left_link.STL" />
      </geometry>
      <material
        name="">
        <color
          rgba="0.75294 0.75294 0.75294 1" />
      </material>
    </visual>
    <collision>
      <origin
        xyz="0 0 0"
        rpy="0 0 0" />
      <geometry>
        <mesh
          filename="package://qxrobot_urdf_v1/meshes/turn_front_left_link.STL" />
      </geometry>
    </collision>
  </link>
  <joint
    name="turn_front_left_link_joint"
    type="continuous">
    <origin
      xyz="0.285 0.215 0.1705"
      rpy="0 0 0" />
    <parent
      link="base_link" />
    <child
      link="turn_front_left_link" />
    <axis
      xyz="0 0 1" />
    <limit
      lower="-9999"
      upper="9999"
      effort="9999"
      velocity="9999" />
    <dynamics
      friction="0.01" />
  </joint>
  <link
    name="wheel_front_left_link">
    <inertial>
      <origin
        xyz="-6.7203E-07 -0.0039185 1.1995E-07"
        rpy="0 0 0" />
      <mass
        value="1.7978" />
      <inertia
        ixx="0.0022135"
        ixy="1.588E-07"
        ixz="2.5603E-08"
        iyy="0.003666"
        iyz="-1.0669E-08"
        izz="0.0022134" />
    </inertial>
    <visual>
      <origin
        xyz="0 0 0"
        rpy="0 0 0" />
      <geometry>
        <mesh
          filename="package://qxrobot_urdf_v1/meshes/wheel_front_left_link.STL" />
      </geometry>
      <material
        name="">
        <color
          rgba="1 0.75294 0.75294 1" />
      </material>
    </visual>
    <collision>
      <origin
        xyz="0 0 0"
        rpy="0 0 0" />
      <geometry>
        <mesh
          filename="package://qxrobot_urdf_v1/meshes/wheel_front_left_link.STL" />
      </geometry>
    </collision>
  </link>
  <joint
    name="wheel_front_left_link_joint"
    type="continuous">
    <origin
      xyz="0 0.0039 -0.101"
      rpy="0 0 0" />
    <parent
      link="turn_front_left_link" />
    <child
      link="wheel_front_left_link" />
    <axis
      xyz="0 1 0" />
    <limit
      lower="-9999"
      upper="9999"
      effort="9999"
      velocity="9999" />
    <dynamics
      friction="0.01" />
  </joint>
  <link
    name="turn_front_right_link">
    <inertial>
      <origin
        xyz="-2.4774E-06 4.2768E-06 -0.041346"
        rpy="0 0 0" />
      <mass
        value="0.1509" />
      <inertia
        ixx="8.621E-05"
        ixy="-2.6953E-09"
        ixz="8.1387E-10"
        iyy="5.4519E-05"
        iyz="-1.5042E-09"
        izz="6.6419E-05" />
    </inertial>
    <visual>
      <origin
        xyz="0 0 0"
        rpy="0 0 0" />
      <geometry>
        <mesh
          filename="package://qxrobot_urdf_v1/meshes/turn_front_right_link.STL" />
      </geometry>
      <material
        name="">
        <color
          rgba="0.75294 0.75294 0.75294 1" />
      </material>
    </visual>
    <collision>
      <origin
        xyz="0 0 0"
        rpy="0 0 0" />
      <geometry>
        <mesh
          filename="package://qxrobot_urdf_v1/meshes/turn_front_right_link.STL" />
      </geometry>
    </collision>
  </link>
  <joint
    name="turn_front_right_link_joint"
    type="continuous">
    <origin
      xyz="0.285 -0.215 0.1705"
      rpy="0 0 0" />
    <parent
      link="base_link" />
    <child
      link="turn_front_right_link" />
    <axis
      xyz="0 -1 0" />
    <limit
      lower="-9999"
      upper="9999"
      effort="9999"
      velocity="9999" />
    <dynamics
      friction="0.01" />
  </joint>
  <link
    name="wheel_front_right_link">
    <inertial>
      <origin
        xyz="6.7203E-07 0.0039185 1.1995E-07"
        rpy="0 0 0" />
      <mass
        value="1.7978" />
      <inertia
        ixx="0.0022135"
        ixy="1.588E-07"
        ixz="-2.5603E-08"
        iyy="0.003666"
        iyz="1.0669E-08"
        izz="0.0022134" />
    </inertial>
    <visual>
      <origin
        xyz="0 0 0"
        rpy="0 0 0" />
      <geometry>
        <mesh
          filename="package://qxrobot_urdf_v1/meshes/wheel_front_right_link.STL" />
      </geometry>
      <material
        name="">
        <color
          rgba="1 0.75294 0.75294 1" />
      </material>
    </visual>
    <collision>
      <origin
        xyz="0 0 0"
        rpy="0 0 0" />
      <geometry>
        <mesh
          filename="package://qxrobot_urdf_v1/meshes/wheel_front_right_link.STL" />
      </geometry>
    </collision>
  </link>
  <joint
    name="wheel_front_right_link_joint"
    type="continuous">
    <origin
      xyz="0 -0.0039 -0.101"
      rpy="0 0 0" />
    <parent
      link="turn_front_right_link" />
    <child
      link="wheel_front_right_link" />
    <axis
      xyz="0 -1 0" />
    <limit
      lower="-9999"
      upper="9999"
      effort="9999"
      velocity="9999" />
    <dynamics
      friction="0.01" />
  </joint>
  <link
    name="turn_back_left_link">
    <inertial>
      <origin
        xyz="2.47739936293234E-06 -0.00390427681696906 0.0596537478356015"
        rpy="0 0 0" />
      <mass
        value="0.150899435444674" />
      <inertia
        ixx="8.62104557625573E-05"
        ixy="-2.69534706876987E-09"
        ixz="-8.13867681148677E-10"
        iyy="5.45191084176943E-05"
        iyz="1.50418273401286E-09"
        izz="6.64192852433824E-05" />
    </inertial>
    <visual>
      <origin
        xyz="0 0 0"
        rpy="0 0 0" />
      <geometry>
        <mesh
          filename="package://qxrobot_urdf_v1/meshes/turn_back_left_link.STL" />
      </geometry>
      <material
        name="">
        <color
          rgba="0.752941176470588 0.752941176470588 0.752941176470588 1" />
      </material>
    </visual>
    <collision>
      <origin
        xyz="0 0 0"
        rpy="0 0 0" />
      <geometry>
        <mesh
          filename="package://qxrobot_urdf_v1/meshes/turn_back_left_link.STL" />
      </geometry>
    </collision>
  </link>
  <joint
    name="turn_back_left_link_joint"
    type="continuous">
    <origin
      xyz="-0.285 0.2189 0.0695"
      rpy="0 0 0" />
    <parent
      link="base_link" />
    <child
      link="turn_back_left_link" />
    <axis
      xyz="0 0 1" />
    <limit
      lower="-9999"
      upper="9999"
      effort="9999"
      velocity="9999" />
    <dynamics
      friction="0.01" />
  </joint>
  <link
    name="wheel_back_left_link">
    <inertial>
      <origin
        xyz="-6.7203E-07 -0.0039185 1.1995E-07"
        rpy="0 0 0" />
      <mass
        value="1.7978" />
      <inertia
        ixx="0.0022135"
        ixy="1.588E-07"
        ixz="2.5603E-08"
        iyy="0.003666"
        iyz="-1.0669E-08"
        izz="0.0022134" />
    </inertial>
    <visual>
      <origin
        xyz="0 0 0"
        rpy="0 0 0" />
      <geometry>
        <mesh
          filename="package://qxrobot_urdf_v1/meshes/wheel_back_left_link.STL" />
      </geometry>
      <material
        name="">
        <color
          rgba="1 0.75294 0.75294 1" />
      </material>
    </visual>
    <collision>
      <origin
        xyz="0 0 0"
        rpy="0 0 0" />
      <geometry>
        <mesh
          filename="package://qxrobot_urdf_v1/meshes/wheel_back_left_link.STL" />
      </geometry>
    </collision>
  </link>
  <joint
    name="wheel_back_left_link_joint"
    type="continuous">
    <origin
      xyz="0 0 0"
      rpy="0 0 0" />
    <parent
      link="turn_back_left_link" />
    <child
      link="wheel_back_left_link" />
    <axis
      xyz="0 -1 0" />
    <limit
      lower="-9999"
      upper="9999"
      effort="9999"
      velocity="9999" />
    <dynamics
      friction="0.01" />
  </joint>
  <link
    name="turn_back_right_link">
    <inertial>
      <origin
        xyz="-2.4774E-06 4.2768E-06 -0.041346"
        rpy="0 0 0" />
      <mass
        value="0.1509" />
      <inertia
        ixx="8.621E-05"
        ixy="-2.6953E-09"
        ixz="8.1387E-10"
        iyy="5.4519E-05"
        iyz="-1.5042E-09"
        izz="6.6419E-05" />
    </inertial>
    <visual>
      <origin
        xyz="0 0 0"
        rpy="0 0 0" />
      <geometry>
        <mesh
          filename="package://qxrobot_urdf_v1/meshes/turn_back_right_link.STL" />
      </geometry>
      <material
        name="">
        <color
          rgba="0.75294 0.75294 0.75294 1" />
      </material>
    </visual>
    <collision>
      <origin
        xyz="0 0 0"
        rpy="0 0 0" />
      <geometry>
        <mesh
          filename="package://qxrobot_urdf_v1/meshes/turn_back_right_link.STL" />
      </geometry>
    </collision>
  </link>
  <joint
    name="turn_back_right_link_joint"
    type="continuous">
    <origin
      xyz="-0.285 -0.215 0.1705"
      rpy="0 0 0" />
    <parent
      link="base_link" />
    <child
      link="turn_back_right_link" />
    <axis
      xyz="0 0 1" />
    <limit
      lower="-9999"
      upper="9999"
      effort="9999"
      velocity="9999" />
    <dynamics
      friction="0.01" />
  </joint>
  <link
    name="wheel_back_right_link">
    <inertial>
      <origin
        xyz="6.7203E-07 0.0039185 1.1995E-07"
        rpy="0 0 0" />
      <mass
        value="1.7978" />
      <inertia
        ixx="0.0022135"
        ixy="1.588E-07"
        ixz="-2.5603E-08"
        iyy="0.003666"
        iyz="1.0669E-08"
        izz="0.0022134" />
    </inertial>
    <visual>
      <origin
        xyz="0 0 0"
        rpy="0 0 0" />
      <geometry>
        <mesh
          filename="package://qxrobot_urdf_v1/meshes/wheel_back_right_link.STL" />
      </geometry>
      <material
        name="">
        <color
          rgba="1 0.75294 0.75294 1" />
      </material>
    </visual>
    <collision>
      <origin
        xyz="0 0 0"
        rpy="0 0 0" />
      <geometry>
        <mesh
          filename="package://qxrobot_urdf_v1/meshes/wheel_back_right_link.STL" />
      </geometry>
    </collision>
  </link>
  <joint
    name="wheel_back_right_link_joint"
    type="continuous">
    <origin
      xyz="0 -0.0039 -0.101"
      rpy="0 0 0" />
    <parent
      link="turn_back_right_link" />
    <child
      link="wheel_back_right_link" />
    <axis
      xyz="0 1 0" />
    <limit
      lower="-9999"
      upper="9999"
      effort="9999"
      velocity="9999" />
  </joint>
  <link
    name="camera_front_link">
    <inertial>
      <origin
        xyz="-0.0046595 0.00026537 3.6317E-05"
        rpy="0 0 0" />
      <mass
        value="0.018758" />
      <inertia
        ixx="1.3987E-05"
        ixy="-4.7593E-09"
        ixz="1.2059E-08"
        iyy="1.7467E-06"
        iyz="-1.0206E-08"
        izz="1.3253E-05" />
    </inertial>
    <visual>
      <origin
        xyz="0 0 0"
        rpy="0 0 0" />
      <geometry>
        <mesh
          filename="package://qxrobot_urdf_v1/meshes/camera_front_link.STL" />
      </geometry>
      <material
        name="">
        <color
          rgba="0.79216 0.81961 0.93333 1" />
      </material>
    </visual>
    <collision>
      <origin
        xyz="0 0 0"
        rpy="0 0 0" />
      <geometry>
        <mesh
          filename="package://qxrobot_urdf_v1/meshes/camera_front_link.STL" />
      </geometry>
    </collision>
  </link>
  <joint
    name="camera_front_llink_joint"
    type="fixed">
    <origin
      xyz="0.36265 0 0.2925"
      rpy="0 0 0" />
    <parent
      link="base_link" />
    <child
      link="camera_front_link" />
    <axis
      xyz="0 0 0" />
  </joint>
  <link
    name="camera_back_link">
    <inertial>
      <origin
        xyz="0.0037648 3.8069E-05 2.4949E-05"
        rpy="0 0 0" />
      <mass
        value="0.059314" />
      <inertia
        ixx="7.025E-06"
        ixy="3.9072E-08"
        ixz="-1.1912E-08"
        iyy="1.2549E-05"
        iyz="-3.1998E-08"
        izz="1.2542E-05" />
    </inertial>
    <visual>
      <origin
        xyz="0 0 0"
        rpy="0 0 0" />
      <geometry>
        <mesh
          filename="package://qxrobot_urdf_v1/meshes/camera_back_link.STL" />
      </geometry>
      <material
        name="">
        <color
          rgba="0.75294 0.75294 0.75294 1" />
      </material>
    </visual>
    <collision>
      <origin
        xyz="0 0 0"
        rpy="0 0 0" />
      <geometry>
        <mesh
          filename="package://qxrobot_urdf_v1/meshes/camera_back_link.STL" />
      </geometry>
    </collision>
  </link>
  <joint
    name="camera_back_llink_joint"
    type="fixed">
    <origin
      xyz="-0.33 0 0.305"
      rpy="0 0 3.1416" />
    <parent
      link="base_link" />
    <child
      link="camera_back_link" />
    <axis
      xyz="0 0 0" />
  </joint>
  <link
    name="imu_link">
    <inertial>
      <origin
        xyz="-2.2669510901796E-07 6.98733953790323E-05 0.00409243345535182"
        rpy="0 0 0" />
      <mass
        value="0.0188120969371347" />
      <inertia
        ixx="2.19917722590059E-06"
        ixy="-1.80548375294379E-13"
        ixz="3.35094597271515E-11"
        iyy="2.54598735456485E-06"
        iyz="-1.1731328952741E-09"
        izz="4.02133166732051E-06" />
    </inertial>
    <visual>
      <origin
        xyz="0 0 0"
        rpy="0 0 0" />
      <geometry>
        <mesh
          filename="package://qxrobot_urdf_v1/meshes/imu_link.STL" />
      </geometry>
      <material
        name="">
        <color
          rgba="0.792156862745098 0.819607843137255 0.933333333333333 1" />
      </material>
    </visual>
    <collision>
      <origin
        xyz="0 0 0"
        rpy="0 0 0" />
      <geometry>
        <mesh
          filename="package://qxrobot_urdf_v1/meshes/imu_link.STL" />
      </geometry>
    </collision>
  </link>
  <joint
    name="imu_link_joint"
    type="fixed">
    <origin
      xyz="-0.315 0 0.3275"
      rpy="0 0 3.1416" />
    <parent
      link="base_link" />
    <child
      link="imu_link" />
    <axis
      xyz="0 0 0" />
  </joint>
  <link
    name="laser_link">
    <inertial>
      <origin
        xyz="-0.00020425 6.2464E-06 -0.032986"
        rpy="0 0 0" />
      <mass
        value="0.2218" />
      <inertia
        ixx="0.00021546"
        ixy="-5.4119E-10"
        ixz="-6.7808E-08"
        iyy="0.00021361"
        iyz="1.1157E-08"
        izz="0.00033669" />
    </inertial>
    <visual>
      <origin
        xyz="0 0 0"
        rpy="0 0 0" />
      <geometry>
        <mesh
          filename="package://qxrobot_urdf_v1/meshes/laser_link.STL" />
      </geometry>
      <material
        name="">
        <color
          rgba="0.75294 0.75294 0.75294 1" />
      </material>
    </visual>
    <collision>
      <origin
        xyz="0 0 0"
        rpy="0 0 0" />
      <geometry>
        <mesh
          filename="package://qxrobot_urdf_v1/meshes/laser_link.STL" />
      </geometry>
    </collision>
  </link>
  <joint
    name="laser_link_joint"
    type="fixed">
    <origin
      xyz="-0.315 0 0.413"
      rpy="0 0 3.1416" />
    <parent
      link="base_link" />
    <child
      link="laser_link" />
    <axis
      xyz="0 0 0" />
  </joint>
  <link
    name="robot_link">
    <inertial>
      <origin
        xyz="0 0 0"
        rpy="0 0 0" />
      <mass
        value="0" />
      <inertia
        ixx="0"
        ixy="0"
        ixz="0"
        iyy="0"
        iyz="0"
        izz="0" />
    </inertial>
  </link>
  <joint
    name="robot_link_joint"
    type="fixed">
    <origin
      xyz="0.282499999999994 0 0.274499999999996"
      rpy="0 0 0" />
    <parent
      link="base_link" />
    <child
      link="robot_link" />
    <axis
      xyz="0 0 0" />
  </joint>
</robot>